Workbook

Sheet Data
A1: user_id | B1: signup_date | C1: experiment_group | D1: region | E1: device_type | F1: traffic_source | G1: plan_type | H1: visited_landing_page | I1: started_trial | J1: completed_onboarding | K1: converted_to_paid | L1: revenue_30d | M1: support_tickets_30d | N1: refund_requested | O1: days_to_convert | P1: engagement_score
A2: USR-100001 | B2: 45732 | C2: Control | D2: North | E2: Desktop | F2: Email | G2: Basic | H2: 0 | I2: 0 | J2: 0 | K2: 0 | L2: 0 | M2: 0 | N2: 0 | P2: 45.7
A3: USR-100002 | B3: 45724 | C3: Control | D3: West | E3: Mobile | F3: Organic | G3: Free | H3: 1 | I3: 0 | J3: 0 | K3: 0 | L3: 0 | M3: 0 | N3: 0 | P3: 48.6 | U3: User Count in Group | W3: Paid Conversion Rate | Y3: Total Revenue Per User
A4: USR-100003 | B4: 45771 | C4: Control | D4: East | E4: Mobile | F4: Paid Search | G4: Premium | H4: 1 | I4: 0 | J4: 0 | K4: 0 | L4: 0 | M4: 1 | N4: 0 | P4: 35.4 | U4: Control | V4: Treatment
A5: USR-100004 | B5: 45781 | C5: Control | D5: South | E5: Mobile | F5: Email | G5: Basic | H5: 1 | I5: 0 | J5: 0 | K5: 0 | L5: 0 | M5: 0 | N5: 0 | P5: 64.6 | T5: North | U5: =COUNTIFS(C2:C1409,"Control",D2:D1409,"North") -> 203 | V5: =COUNTIFS(C2:C1409,"Treatment",D2:D1409,"North") -> 180 | W5: =COUNTIFS(K2:K1409,"<>0",D2:D1409,"North") -> 23
A6: USR-100005 | B6: 45700 | C6: Control | D6: North | E6: Tablet | F6: Organic | G6: Free | H6: 0 | I6: 0 | J6: 0 | K6: 0 | L6: 0 | M6: 0 | N6: 0 | P6: 66.6 | T6: South | U6: =COUNTIFS(C3:C1409,"Control",D3:D1409,"South") -> 184 | V6: =COUNTIFS(C2:C1409,"Treatment",D2:D1409,"South") -> 184
A7: USR-100006 | B7: 45685 | C7: Control | D7: East | E7: Mobile | F7: Organic | G7: Premium | H7: 1 | I7: 0 | J7: 0 | K7: 0 | L7: 0 | M7: 0 | N7: 0 | P7: 40.8 | T7: East | U7: =COUNTIFS(C4:C1409,"Control",D4:D1409,"East") -> 158 | V7: =COUNTIFS(C2:C1409,"Treatment",D2:D1409,"East") -> 172
A8: USR-100007 | B8: 45755 | C8: Control | D8: East | E8: Mobile | F8: Paid Search | G8: Basic | H8: 1 | I8: 1 | J8: 0 | K8: 0 | L8: 0 | M8: 0 | N8: 0 | P8: 57.1 | T8: West | U8: =COUNTIFS(C5:C1409,"Control",D5:D1409,"East") -> 157 | V8: =COUNTIFS(C2:C1409,"Treatment",D2:D1409,"West") -> 179
A9: USR-100008 | B9: 45794 | C9: Control | D9: South | E9: Mobile | F9: Paid Search | G9: Free | H9: 0 | I9: 0 | J9: 0 | K9: 0 | L9: 0 | M9: 0 | N9: 0 | P9: 36.4 | U9: =SUM(U5:U8) -> 702 | V9: =SUM(V5:V8) -> 715
A10: USR-100009 | B10: 45711 | C10: Control | D10: South | E10: Tablet | F10: Referral | G10: Basic | H10: 0 | I10: 0 | J10: 0 | K10: 0 | L10: 0 | M10: 0 | N10: 0 | P10: 55.4
A11: USR-100010 | B11: 45806 | C11: Control | D11: West | E11: Desktop | F11: Social | G11: Free | H11: 1 | I11: 0 | J11: 0 | K11: 0 | L11: 0 | M11: 0 | N11: 0 | P11: 57.3
A12: USR-100011 | B12: 45777 | C12: Control | D12: East | E12: Mobile | F12: Paid Search | G12: Basic | H12: 1 | I12: 1 | J12: 1 | K12: 0 | L12: 0 | M12: 0 | N12: 0 | P12: 63.6
A13: USR-100012 | B13: 45732 | C13: Control | D13: East | E13: Mobile | F13: Social | G13: Premium | H13: 1 | I13: 1 | J13: 1 | K13: 0 | L13: 0 | M13: 1 | N13: 0 | P13: 80.4
A14: USR-100013 | B14: 45695 | C14: Control | D14: South | E14: Desktop | F14: Email | G14: Basic | H14: 1 | I14: 0 | J14: 0 | K14: 0 | L14: 0 | M14: 0 | N14: 0 | P14: 62.4
A15: USR-100014 | B15: 45718 | C15: Control | D15: West | E15: Mobile | F15: Social | G15: Basic | H15: 1 | I15: 0 | J15: 0 | K15: 0 | L15: 0 | M15: 0 | N15: 0 | P15: 82.4
A16: USR-100015 | B16: 45807 | C16: Control | D16: South | E16: Mobile | F16: Organic | G16: Basic | H16: 0 | I16: 0 | J16: 0 | K16: 0 | L16: 0 | M16: 0 | N16: 0 | P16: 61.2
A17: USR-100016 | B17: 45741 | C17: Control | D17: South | E17: Mobile | F17: Social | G17: Basic | H17: 1 | I17: 0 | J17: 0 | K17: 0 | L17: 0 | M17: 0 | N17: 0 | P17: 68.9
A18: USR-100017 | B18: 45743 | C18: Control | D18: East | E18: Desktop | F18: Paid Search | G18: Free | H18: 1 | I18: 1 | J18: 1 | K18: 0 | L18: 0 | M18: 0 | N18: 0 | P18: 71.9
A19: USR-100018 | B19: 45805 | C19: Control | D19: South | E19: Desktop | F19: Paid Search | G19: Free | H19: 0 | I19: 0 | J19: 0 | K19: 0 | L19: 0 | M19: 0 | N19: 0 | P19: 50.5
A20: USR-100019 | B20: 45703 | C20: Control | D20: North | E20: Desktop | F20: Paid Search | G20: Basic | H20: 0 | I20: 0 | J20: 0 | K20: 0 | L20: 0 | M20: 0 | N20: 0 | P20: 49.3
A21: USR-100020 | B21: 45782 | C21: Control | D21: West | E21: Desktop | F21: Organic | G21: Basic | H21: 0 | I21: 0 | J21: 0 | K21: 0 | L21: 0 | M21: 2 | N21: 0 | P21: 60.9
... A60: USR-100059 | B60: 45761 | C60: Control | D60: North | E60: Mobile | F60: Social | G60: Free | H60: 0 | I60: 0 | J60: 0 | K60: 0 | L60: 0 | M60: 2 | N60: 0 | P60: 48.9
A61: USR-100060 | B61: 45658 | C61: Control | D61: West | E61: Mobile | F61: Social | G61: Free | H61: 1 | I61: 1 | J61: 1 | K61: 1 | L61: 240.42 | M61: 0 | N61: 0 | O61: 16 | P61: 56.5
A62: USR-100061 | B62: 45749 | C62: Control | D62: South | E62: Mobile | F62: Referral | G62: Free | H62: 1 | I62: 0 | J62: 0 | K62: 0 | L62: 0 | M62: 0 | N62: 0 | P62: 53.7
A63: USR-100062 | B63: 45745 | C63: Control | D63: North | E63: Mobile | F63: Social | G63: Premium | H63: 0 | I63: 0 | J63: 0 | K63: 0 | L63: 0 | M63: 0 | N63: 0 | P63: 62.2
A64: USR-100063 | B64: 45792 | C64: Control | D64: South | E64: Desktop | F64: Organic | G64: Free | H64: 1 | I64: 0 | J64: 0 | K64: 0 | L64: 0 | M64: 0 | N64: 0 | P64: 50.2
A65: USR-100064 | B65: 45758 | C65: Control | D65: North | E65: Mobile | F65: Organic | G65: Basic | H65: 1 | I65: 0 | J65: 0 | K65: 0 | L65: 0 | M65: 0 | N65: 0 | P65: 74.3
A66: USR-100065 | B66: 45723 | C66: Control | D66: South | E66: Desktop | F66: Paid Search | G66: Free | H66: 1 | I66: 0 | J66: 0 | K66: 0 | L66: 0 | M66: 0 | N66: 0 | P66: 58
A67: USR-100066 | B67: 45807 | C67: Control | D67: South | E67: Mobile | F67: Organic | G67: Free | H67: 0 | I67: 0 | J67: 0 | K67: 0 | L67: 0 | M67: 0 | N67: 0 | P67: 46.7
A68: USR-100067 | B68: 45664 | C68: Control | D68: South | E68: Desktop | F68: Organic | G68: Premium | H68: 1 | I68: 0 | J68: 0 | K68: 0 | L68: 0 | M68: 1 | N68: 0 | P68: 49.6
A69: USR-100068 | B69: 45785 | C69: Control | D69: West | E69: Mobile | F69: Social | G69: Free | H69: 0 | I69: 0 | J69: 0 | K69: 0 | L69: 0 | M69: 0 | N69: 0 | P69: 60.4
A70: USR-100069 | B70: 45735 | C70: Control | D70: East | E70: Desktop | F70: Email | G70: Free | H70: 1 | I70: 1 | J70: 1 | K70: 0 | L70: 0 | M70: 0 | N70: 0 | P70: 55.3
A71: USR-100070 | B71: 45793 | C71: Control | D71: North | E71: Desktop | F71: Organic | G71: Free | H71: 0 | I71: 0 | J71: 0 | K71: 0 | L71: 0 | M71: 0 | N71: 0 | P71: 56.2
A72: USR-100071 | B72: 45724 | C72: Control | D72: West | E72: Mobile | F72: Email | G72: Free | H72: 0 | I72: 0 | J72: 0 | K72: 0 | L72: 0 | M72: 0 | N72: 0 | P72: 29.4
A73: USR-100072 | B73: 45724 | C73: Control | D73: East | E73: Mobile | F73: Email | G73: Free | H73: 1 | I73: 0 | J73: 0 | K73: 0 | L73: 0 | M73: 0 | N73: 0 | P73: 54.2
... A79: USR-100078 | B79: 45673 | C79: Control | D79: North | E79: Mobile | F79: Organic | G79: Free | H79: 0 | I79: 0 | J79: 0 | K79: 0 | L79: 0 | M79: 2 | N79: 0 | P79: 48.4
A80: USR-100079 | B80: 45708 | C80: Control | D80: West | E80: Desktop | F80: Organic | G80: Free | H80: 1 | I80: 1 | J80: 1 | K80: 1 | L80: 457.51 | M80: 0 | N80: 0 | O80: 7 | P80: 38
A81: USR-100080 | B81: 45798 | C81: Control | D81: East | E81: Mobile | F81: Social | G81: Free | H81: 1 | I81: 0 | J81: 0 | K81: 0 | L81: 0 | M81: 0 | N81: 0 | P81: 44.2
A82: USR-100081 | B82: 45785 | C82: Control | D82: South | E82: Mobile | F82: Organic | G82: Free | H82: 1 | I82: 1 | J82: 1 | K82: 0 | L82: 0 | M82: 0 | N82: 0 | P82: 81.2
A83: USR-100082 | B83: 45724 | C83: Control | D83: South | E83: Mobile | F83: Referral | G83: Free | H83: 1 | I83: 1 | J83: 0 | K83: 0 | L83: 0 | M83: 0 | N83: 0 | P83: 63.8
...

Sheet Region
B1: User Count in Group | D1: Total Users | E1: Paid Conversion Rate | G1: Average revenue per user
B2: Control | C2: Treatment | E2: No of users converted to paid | F2: Users converted to paid / total users | G2: Total Revenue | H2: Total revenue / total users
A3: North | B3: =COUNTIFS(Data!$C$2:'Data'!$C$1409,"Control",Data!$D$2:'Data'!$D$1409,"North") -> 203 | C3: =COUNTIFS(Data!$C$2:'Data'!$C$1409,"Treatment",Data!$D$2:'Data'!$D$1409,"North") -> 180 | D3: =B3+C3 -> 383 | E3: =COUNTIFS(Data!$K$2:'Data'!$K$1409,"<>0",Data!$D$2:'Data'!$D$1409,"North") -> 23 | F3: =E3/D3 -> 0.060052219 | G3: =SUMIF(Data!$D$2:'Data'!$D$1409,"North",Data!$L$2:'Data'!$L$1409) -> 31558.67 | H3: =G3/D3 -> 82.398616
A4: South | B4: =COUNTIFS(Data!$C$2:'Data'!$C$1409,"Control",Data!$D$2:'Data'!$D$1409,"South") -> 184 | C4: =COUNTIFS(Data!$C$2:'Data'!$C$1409,"Treatment",Data!$D$2:'Data'!$D$1409,"South") -> 184 | D4: =B4+C4 -> 368 | E4: =COUNTIFS(Data!$K$2:'Data'!$K$1409,"<>0",Data!$D$2:'Data'!$D$1409,"South") -> 20 | F4: =E4/D4 -> 0.054347826 | G4: =SUMIF(Data!$D$2:'Data'!$D$1409,"South",Data!$L$2:'Data'!$L$1409) -> 22638.4 | H4: =G4/D4 -> 61.517391
A5: East | B5: =COUNTIFS(Data!$C$2:'Data'!$C$1409,"Control",Data!$D$2:'Data'!$D$1409,"East") -> 158 | C5: =COUNTIFS(Data!$C$2:'Data'!$C$1409,"Treatment",Data!$D$2:'Data'!$D$1409,"East") -> 172 | D5: =B5+C5 -> 330 | E5: =COUNTIFS(Data!$K$2:'Data'!$K$1409,"<>0",Data!$D$2:'Data'!$D$1409,"East") -> 15 | F5: =E5/D5 -> 0.045454545 | G5: =SUMIF(Data!$D$2:'Data'!$D$1409,"East",Data!$L$2:'Data'!$L$1409) -> 10861.14 | H5: =G5/D5 -> 32.912545
A6: West | B6: =COUNTIFS(Data!$C$2:'Data'!$C$1409,"Control",Data!$D$2:'Data'!$D$1409,"West") -> 148 | C6: =COUNTIFS(Data!$C$2:'Data'!$C$1409,"Treatment",Data!$D$2:'Data'!$D$1409,"West") -> 179 | D6: =B6+C6 -> 327 | E6: =COUNTIFS(Data!$K$2:'Data'!$K$1409,"<>0",Data!$D$2:'Data'!$D$1409,"West") -> 14 | F6: =E6/D6 -> 0.042813456 | G6: =SUMIF(Data!$D$2:'Data'!$D$1409,"West",Data!$L$2:'Data'!$L$1409) -> 9324.78 | H6: =G6/D6 -> 28.516147
B7: =SUM(B3:B6) -> 693 | C7: =SUM(C3:C6) -> 715 | D7: =B7+C7 -> 1408 | E7: =SUM(E3:E6) -> 72 | F7: =E7/D7 -> 0.051136364 | G7: =SUM(G3:G6) -> 74382.99 | H7: =G7/D7 -> 52.828828

Sheet Device Type
B1: User Count in Group | D1: Total Users | E1: Paid Conversion Rate | G1: Average revenue per user
B2: Control | C2: Treatment | E2: No of users converted to paid | F2: Users converted to paid / total users | G2: Total Revenue | H2: Total revenue / total users
A3: Desktop | B3: =COUNTIFS(Data!$C$2:'Data'!$C$1409,"Control",Data!$E$2:'Data'!$E$1409,"Desktop") -> 200 | C3: =COUNTIFS(Data!$C$2:'Data'!$C$1409,"Treatment",Data!$E$2:'Data'!$E$1409,"Desktop") -> 214 | D3: =B3+C3 -> 414 | E3: =COUNTIFS(Data!$K$2:'Data'!$K$1409,"<>0",Data!$E$2:'Data'!$E$1409,"Desktop") -> 23 | F3: =E3/D3 -> 0.055555556 | G3: =SUMIF(Data!$E$2:'Data'!$E$1409,"Desktop",Data!$L$2:'Data'!$L$1409) -> 25753.63 | H3: =G3/D3 -> 62.206836
A4: Mobile | B4: =COUNTIFS(Data!$C$2:'Data'!$C$1409,"Control",Data!$E$2:'Data'!$E$1409,"Mobile") -> 428 | C4: =COUNTIFS(Data!$C$2:'Data'!$C$1409,"Treatment",Data!$E$2:'Data'!$E$1409,"Mobile") -> 436 | D4: =B4+C4 -> 864 | E4: =COUNTIFS(Data!$K$2:'Data'!$K$1409,"<>0",Data!$E$2:'Data'!$E$1409,"Mobile") -> 43 | F4: =E4/D4 -> 0.049768519 | G4: =SUMIF(Data!$E$2:'Data'!$E$1409,"Mobile",Data!$L$2:'Data'!$L$1409) -> 43560.09 | H4: =G4/D4 -> 50.416771
A5: Tablet | B5: =COUNTIFS(Data!$C$2:'Data'!$C$1409,"Control",Data!$E$2:'Data'!$E$1409,"Tablet") -> 56 | C5: =COUNTIFS(Data!$C$2:'Data'!$C$1409,"Treatment",Data!$E$2:'Data'!$E$1409,"Tablet") -> 56 | D5: =B5+C5 -> 112 | E5: =COUNTIFS(Data!$K$2:'Data'!$K$1409,"<>0",Data!$E$2:'Data'!$E$1409,"Tablet") -> 5 | F5: =E5/D5 -> 0.044642857 | G5: =SUMIF(Data!$E$2:'Data'!$E$1409,"Tablet",Data!$L$2:'Data'!$L$1409) -> 4515.9 | H5: =G5/D5 -> 40.320536
A6: (Blank) | B6: =COUNTIFS(Data!$C$2:'Data'!$C$1409,"Control",Data!$E$2:'Data'!$E$1409,"") -> 9 | C6: =COUNTIFS(Data!$C$2:'Data'!$C$1409,"Treatment",Data!$E$2:'Data'!$E$1409,"") -> 9 | D6: =B6+C6 -> 18 | E6: =COUNTIFS(Data!$K$2:'Data'!$K$1409,"<>0",Data!$E$2:'Data'!$E$1409,"") -> 1 | F6: =COUNTIFS(Data!$K$2:'Data'!$K$1409,"<>0",Data!$E$2:'Data'!$E$1409,"") -> 1 | G6: =SUMIF(Data!$E$2:'Data'!$E$1409,"",Data!$L$2:'Data'!$L$1409) -> 553.37 | H6: =G6/D6 -> 30.742778
B7: =SUM(B3:B6) -> 693 | C7: =SUM(C3:C6) -> 715 | D7: =B7+C7 -> 1408 | E7: =SUM(E3:E6) -> 72 | F7: =E7/D7 -> 0.051136364 | G7: =SUM(G3:G6) -> 74382.99 | H7: =G7/D7 -> 52.828828

Sheet Traffic Source
B1: User Count in Group | D1: Total Users | E1: Paid Conversion Rate | G1: Average revenue per user
B2: Control | C2: Treatment | E2: No of users converted to paid | F2: Users converted to paid / total users | G2: Total Revenue | H2: Total revenue / total users
A3: Email | B3: =COUNTIFS(Data!$C$2:'Data'!$C$1409,"Control",Data!$F$2:'Data'!$F$1409,"Email") -> 74 | C3: =COUNTIFS(Data!$C$2:'Data'!$C$1409,"Treatment",Data!$F$2:'Data'!$F$1409,"Email") -> 56 | D3: =B3+C3 -> 130 | E3: =COUNTIFS(Data!$K$2:'Data'!$K$1409,"<>0",Data!$F$2:'Data'!$F$1409,"Email") -> 6 | F3: =E3/D3 -> 0.046153846 | G3: =SUMIF(Data!$F$2:'Data'!$F$1409,"Email",Data!$L$2:'Data'!$L$1409) -> 4644.26 | H3: =G3/D3 -> 35.725077
A4: Organic | B4: =COUNTIFS(Data!$C$2:'Data'!$C$1409,"Control",Data!$F$2:'Data'!$F$1409,"Organic") -> 246 | C4: =COUNTIFS(Data!$C$2:'Data'!$C$1409,"Treatment",Data!$F$2:'Data'!$F$1409,"Organic") -> 241 | D4: =B4+C4 -> 487 | E4: =COUNTIFS(Data!$K$2:'Data'!$K$1409,"<>0",Data!$F$2:'Data'!$F$1409,"Organic") -> 20 | F4: =E4/D4 -> 0.041067762 | G4: =SUMIF(Data!$F$2:'Data'!$F$1409,"Organic",Data!$L$2:'Data'!$L$1409) -> 22678.34 | H4: =G4/D4 -> 46.567433
A5: Paid Search | B5: =COUNTIFS(Data!$C$2:'Data'!$C$1409,"Control",Data!$F$2:'Data'!$F$1409,"Paid Search") -> 156 | C5: =COUNTIFS(Data!$C$2:'Data'!$C$1409,"Treatment",Data!$F$2:'Data'!$F$1409,"Paid Search") -> 176 | D5: =B5+C5 -> 332 | E5: =COUNTIFS(Data!$K$2:'Data'!$K$1409,"<>0",Data!$F$2:'Data'!$F$1409,"Paid Search") -> 13 | F5: =E5/D5 -> 0.039156627 | G5: =SUMIF(Data!$F$2:'Data'!$F$1409,"Paid Search",Data!$L$2:'Data'!$L$1409) -> 7812.2 | H5: =G5/D5 -> 23.530723
A6: Referral | B6: =COUNTIFS(Data!$C$2:'Data'!$C$1409,"Control",Data!$F$2:'Data'!$F$1409,"Referral") -> 81 | C6: =COUNTIFS(Data!$C$2:'Data'!$C$1409,"Treatment",Data!$F$2:'Data'!$F$1409,"Referral") -> 91 | D6: =B6+C6 -> 172 | E6: =COUNTIFS(Data!$K$2:'Data'!$K$1409,"<>0",Data!$F$2:'Data'!$F$1409,"Referral") -> 12 | F6: =E6/D6 -> 0.069767442 | G6: =SUMIF(Data!$F$2:'Data'!$F$1409,"Referral",Data!$L$2:'Data'!$L$1409) -> 12071.57 | H6: =G6/D6 -> 70.183547
A7: Social | B7: =COUNTIFS(Data!$C$2:'Data'!$C$1409,"Control",Data!$F$2:'Data'!$F$1409,"Social") -> 130 | C7: =COUNTIFS(Data!$C$2:'Data'!$C$1409,"Treatment",Data!$F$2:'Data'!$F$1409,"Social") -> 133 | D7: =B7+C7 -> 263 | E7: =COUNTIFS(Data!$K$2:'Data'!$K$1409,"<>0",Data!$F$2:'Data'!$F$1409,"Social") -> 18 | F7: =E7/D7 -> 0.068441065 | G7: =SUMIF(Data!$F$2:'Data'!$F$1409,"Social",Data!$L$2:'Data'!$L$1409) -> 24547.76 | H7: =G7/D7 -> 93.33749
A8: (Blank) | B8: =COUNTIFS(Data!$C$2:'Data'!$C$1409,"Control",Data!$F$2:'Data'!$F$1409,"") -> 6 | C8: =COUNTIFS(Data!$C$2:'Data'!$C$1409,"Treatment",Data!$F$2:'Data'!$F$1409,"") -> 18 | D8: =B8+C8 -> 24 | E8: =COUNTIFS(Data!$K$2:'Data'!$K$1409,"<>0",Data!$F$2:'Data'!$F$1409,"") -> 3 | F8: =E8/D8 -> 0.125 | G8: =SUMIF(Data!$F$2:'Data'!$F$1409,"",Data!$L$2:'Data'!$L$1409) -> 2628.86 | H8: =G8/D8 -> 109.53583
B9: =SUM(B3:B8) -> 693 | C9: =SUM(C3:C8) -> 715 | D9: =B9+C9 -> 1408 | E9: =SUM(E3:E8) -> 72 | F9: =E9/D9 -> 0.051136364 | G9: =SUM(G3:G8) -> 74382.99 | H9: =G9/D9 -> 52.828828

Sheet Plan Type
B1: User Count in Group | D1: Total Users | E1: Paid Conversion Rate | G1: Average revenue per user
B2: Control | C2: Treatment | E2: No of users converted to paid | F2: Users converted to paid / total users | G2: Total Revenue | H2: Total revenue / total users
A3: Basic | B3: =COUNTIFS(Data!$C$2:'Data'!$C$1409,"Control",Data!$G$2:'Data'!$G$1409,"Basic") -> 223 | C3: =COUNTIFS(Data!$C$2:'Data'!$C$1409,"Treatment",Data!$G$2:'Data'!$G$1409,"Basic") -> 235 | D3: =B3+C3 -> 458 | E3: =COUNTIFS(Data!$K$2:'Data'!$K$1409,"<>0",Data!$G$2:'Data'!$G$1409,"Basic") -> 17 | F3: =E3/D3 -> 0.037117904 | G3: =SUMIF(Data!$G$2:'Data'!$G$1409,"Basic",Data!$L$2:'Data'!$L$1409) -> 30337.29 | H3: =G3/D3 -> 66.238624
A4: Free | B4: =COUNTIFS(Data!$C$2:'Data'!$C$1409,"Control",Data!$G$2:'Data'!$G$1409,"Free") -> 361 | C4: =COUNTIFS(Data!$C$2:'Data'!$C$1409,"Treatment",Data!$G$2:'Data'!$G$1409,"Free") -> 368 | D4: =B4+C4 -> 729 | E4: =COUNTIFS(Data!$K$2:'Data'!$K$1409,"<>0",Data!$G$2:'Data'!$G$1409,"Free") -> 45 | F4: =E4/D4 -> 0.061728395 | G4: =SUMIF(Data!$G$2:'Data'!$G$1409,"Free",Data!$L$2:'Data'!$L$1409) -> 26912.49 | H4: =G4/D4 -> 36.916996
A5: Premium | B5: =COUNTIFS(Data!$C$2:'Data'!$C$1409,"Control",Data!$G$2:'Data'!$G$1409,"Premium") -> 109 | C5: =COUNTIFS(Data!$C$2:'Data'!$C$1409,"Treatment",Data!$G$2:'Data'!$G$1409,"Premium") -> 112 | D5: =B5+C5 -> 221 | E5: =COUNTIFS(Data!$K$2:'Data'!$K$1409,"<>0",Data!$G$2:'Data'!$G$1409,"Premium") -> 10 | F5: =E5/D5 -> 0.045248869 | G5: =SUMIF(Data!$G$2:'Data'!$G$1409,"Premium",Data!$L$2:'Data'!$L$1409) -> 17133.21 | H5: =G5/D5 -> 77.525837
B6: =SUM(B3:B5) -> 693 | C6: =SUM(C3:C5) -> 715 | D6: =B6+C6 -> 1408 | E6: =SUM(E3:E5) -> 72 | F6: =E6/D6 -> 0.051136364 | G6: =SUM(G3:G5) -> 74382.99 | H6: =G6/D6 -> 52.828828
